test_apiDescription (__main__.TestAPIEndpoints.test_apiDescription) ... ERROR
test_getProducts (__main__.TestAPIEndpoints.test_getProducts) ... ERROR
test_getTitles (__main__.TestAPIEndpoints.test_getTitles) ... ERROR
test_insertProduct (__main__.TestAPIEndpoints.test_insertProduct) ... ERROR

======================================================================
ERROR: test_apiDescription (__main__.TestAPIEndpoints.test_apiDescription)
----------------------------------------------------------------------
Traceback (most recent call last):
  File "C:\Users\paulj\AppData\Local\Programs\Python\Python311\Lib\site-packages\urllib3\connection.py", line 174, in _new_conn
    conn = connection.create_connection(
           ^^^^^^^^^^^^^^^^^^^^^^^^^^^^^
  File "C:\Users\paulj\AppData\Local\Programs\Python\Python311\Lib\site-packages\urllib3\util\connection.py", line 95, in create_connection
    raise err
  File "C:\Users\paulj\AppData\Local\Programs\Python\Python311\Lib\site-packages\urllib3\util\connection.py", line 85, in create_connection
    sock.connect(sa)
ConnectionRefusedError: [WinError 10061] No connection could be made because the target machine actively refused it

During handling of the above exception, another exception occurred:

Traceback (most recent call last):
  File "C:\Users\paulj\AppData\Local\Programs\Python\Python311\Lib\site-packages\urllib3\connectionpool.py", line 703, in urlopen
    httplib_response = self._make_request(
                       ^^^^^^^^^^^^^^^^^^^
  File "C:\Users\paulj\AppData\Local\Programs\Python\Python311\Lib\site-packages\urllib3\connectionpool.py", line 398, in _make_request
    conn.request(method, url, **httplib_request_kw)
  File "C:\Users\paulj\AppData\Local\Programs\Python\Python311\Lib\site-packages\urllib3\connection.py", line 239, in request
    super(HTTPConnection, self).request(method, url, body=body, headers=headers)
  File "C:\Users\paulj\AppData\Local\Programs\Python\Python311\Lib\http\client.py", line 1282, in request
    self._send_request(method, url, body, headers, encode_chunked)
  File "C:\Users\paulj\AppData\Local\Programs\Python\Python311\Lib\http\client.py", line 1328, in _send_request
    self.endheaders(body, encode_chunked=encode_chunked)
  File "C:\Users\paulj\AppData\Local\Programs\Python\Python311\Lib\http\client.py", line 1277, in endheaders
    self._send_output(message_body, encode_chunked=encode_chunked)
  File "C:\Users\paulj\AppData\Local\Programs\Python\Python311\Lib\http\client.py", line 1037, in _send_output
    self.send(msg)
  File "C:\Users\paulj\AppData\Local\Programs\Python\Python311\Lib\http\client.py", line 975, in send
    self.connect()
  File "C:\Users\paulj\AppData\Local\Programs\Python\Python311\Lib\site-packages\urllib3\connection.py", line 205, in connect
    conn = self._new_conn()
           ^^^^^^^^^^^^^^^^
  File "C:\Users\paulj\AppData\Local\Programs\Python\Python311\Lib\site-packages\urllib3\connection.py", line 186, in _new_conn
    raise NewConnectionError(
urllib3.exceptions.NewConnectionError: <urllib3.connection.HTTPConnection object at 0x000001797A55C710>: Failed to establish a new connection: [WinError 10061] No connection could be made because the target machine actively refused it

During handling of the above exception, another exception occurred:

Traceback (most recent call last):
  File "C:\Users\paulj\AppData\Local\Programs\Python\Python311\Lib\site-packages\requests\adapters.py", line 486, in send
    resp = conn.urlopen(
           ^^^^^^^^^^^^^
  File "C:\Users\paulj\AppData\Local\Programs\Python\Python311\Lib\site-packages\urllib3\connectionpool.py", line 787, in urlopen
    retries = retries.increment(
              ^^^^^^^^^^^^^^^^^^
  File "C:\Users\paulj\AppData\Local\Programs\Python\Python311\Lib\site-packages\urllib3\util\retry.py", line 592, in increment
    raise MaxRetryError(_pool, url, error or ResponseError(cause))
urllib3.exceptions.MaxRetryError: HTTPConnectionPool(host='127.0.0.1', port=5000): Max retries exceeded with url: / (Caused by NewConnectionError('<urllib3.connection.HTTPConnection object at 0x000001797A55C710>: Failed to establish a new connection: [WinError 10061] No connection could be made because the target machine actively refused it'))

During handling of the above exception, another exception occurred:

Traceback (most recent call last):
  File "c:\Users\paulj\OneDrive\Desktop\WS-2024\AssignmentUnitTest.py", line 40, in test_apiDescription
    response = requests.get(url)
               ^^^^^^^^^^^^^^^^^
  File "C:\Users\paulj\AppData\Local\Programs\Python\Python311\Lib\site-packages\requests\api.py", line 73, in get
    return request("get", url, params=params, **kwargs)
           ^^^^^^^^^^^^^^^^^^^^^^^^^^^^^^^^^^^^^^^^^^^^
  File "C:\Users\paulj\AppData\Local\Programs\Python\Python311\Lib\site-packages\requests\api.py", line 59, in request
    return session.request(method=method, url=url, **kwargs)
           ^^^^^^^^^^^^^^^^^^^^^^^^^^^^^^^^^^^^^^^^^^^^^^^^^
  File "C:\Users\paulj\AppData\Local\Programs\Python\Python311\Lib\site-packages\requests\sessions.py", line 589, in request
    resp = self.send(prep, **send_kwargs)
           ^^^^^^^^^^^^^^^^^^^^^^^^^^^^^^
  File "C:\Users\paulj\AppData\Local\Programs\Python\Python311\Lib\site-packages\requests\sessions.py", line 703, in send
    r = adapter.send(request, **kwargs)
        ^^^^^^^^^^^^^^^^^^^^^^^^^^^^^^^
  File "C:\Users\paulj\AppData\Local\Programs\Python\Python311\Lib\site-packages\requests\adapters.py", line 519, in send
    raise ConnectionError(e, request=request)
requests.exceptions.ConnectionError: HTTPConnectionPool(host='127.0.0.1', port=5000): Max retries exceeded with url: / (Caused by NewConnectionError('<urllib3.connection.HTTPConnection object at 0x000001797A55C710>: Failed to establish a new connection: [WinError 10061] No connection could be made because the target machine actively refused it'))

======================================================================
ERROR: test_getProducts (__main__.TestAPIEndpoints.test_getProducts)
----------------------------------------------------------------------
Traceback (most recent call last):
  File "C:\Users\paulj\AppData\Local\Programs\Python\Python311\Lib\site-packages\urllib3\connection.py", line 174, in _new_conn
    conn = connection.create_connection(
           ^^^^^^^^^^^^^^^^^^^^^^^^^^^^^
  File "C:\Users\paulj\AppData\Local\Programs\Python\Python311\Lib\site-packages\urllib3\util\connection.py", line 95, in create_connection
    raise err
  File "C:\Users\paulj\AppData\Local\Programs\Python\Python311\Lib\site-packages\urllib3\util\connection.py", line 85, in create_connection
    sock.connect(sa)
ConnectionRefusedError: [WinError 10061] No connection could be made because the target machine actively refused it

During handling of the above exception, another exception occurred:

Traceback (most recent call last):
  File "C:\Users\paulj\AppData\Local\Programs\Python\Python311\Lib\site-packages\urllib3\connectionpool.py", line 703, in urlopen
    httplib_response = self._make_request(
                       ^^^^^^^^^^^^^^^^^^^
  File "C:\Users\paulj\AppData\Local\Programs\Python\Python311\Lib\site-packages\urllib3\connectionpool.py", line 398, in _make_request
    conn.request(method, url, **httplib_request_kw)
  File "C:\Users\paulj\AppData\Local\Programs\Python\Python311\Lib\site-packages\urllib3\connection.py", line 239, in request
    super(HTTPConnection, self).request(method, url, body=body, headers=headers)
  File "C:\Users\paulj\AppData\Local\Programs\Python\Python311\Lib\http\client.py", line 1282, in request
    self._send_request(method, url, body, headers, encode_chunked)
  File "C:\Users\paulj\AppData\Local\Programs\Python\Python311\Lib\http\client.py", line 1328, in _send_request
    self.endheaders(body, encode_chunked=encode_chunked)
  File "C:\Users\paulj\AppData\Local\Programs\Python\Python311\Lib\http\client.py", line 1277, in endheaders
    self._send_output(message_body, encode_chunked=encode_chunked)
  File "C:\Users\paulj\AppData\Local\Programs\Python\Python311\Lib\http\client.py", line 1037, in _send_output
    self.send(msg)
  File "C:\Users\paulj\AppData\Local\Programs\Python\Python311\Lib\http\client.py", line 975, in send
    self.connect()
  File "C:\Users\paulj\AppData\Local\Programs\Python\Python311\Lib\site-packages\urllib3\connection.py", line 205, in connect
    conn = self._new_conn()
           ^^^^^^^^^^^^^^^^
  File "C:\Users\paulj\AppData\Local\Programs\Python\Python311\Lib\site-packages\urllib3\connection.py", line 186, in _new_conn
    raise NewConnectionError(
urllib3.exceptions.NewConnectionError: <urllib3.connection.HTTPConnection object at 0x000001797A55C890>: Failed to establish a new connection: [WinError 10061] No connection could be made because the target machine actively refused it

During handling of the above exception, another exception occurred:

Traceback (most recent call last):
  File "C:\Users\paulj\AppData\Local\Programs\Python\Python311\Lib\site-packages\requests\adapters.py", line 486, in send
    resp = conn.urlopen(
           ^^^^^^^^^^^^^
  File "C:\Users\paulj\AppData\Local\Programs\Python\Python311\Lib\site-packages\urllib3\connectionpool.py", line 787, in urlopen
    retries = retries.increment(
              ^^^^^^^^^^^^^^^^^^
  File "C:\Users\paulj\AppData\Local\Programs\Python\Python311\Lib\site-packages\urllib3\util\retry.py", line 592, in increment
    raise MaxRetryError(_pool, url, error or ResponseError(cause))
urllib3.exceptions.MaxRetryError: HTTPConnectionPool(host='127.0.0.1', port=5000): Max retries exceeded with url: /getProducts (Caused by NewConnectionError('<urllib3.connection.HTTPConnection object at 0x000001797A55C890>: Failed to establish a new connection: [WinError 10061] No connection could be made because the target machine actively refused it'))

During handling of the above exception, another exception occurred:

Traceback (most recent call last):
  File "c:\Users\paulj\OneDrive\Desktop\WS-2024\AssignmentUnitTest.py", line 18, in test_getProducts
    response = requests.get(url)
               ^^^^^^^^^^^^^^^^^
  File "C:\Users\paulj\AppData\Local\Programs\Python\Python311\Lib\site-packages\requests\api.py", line 73, in get
    return request("get", url, params=params, **kwargs)
           ^^^^^^^^^^^^^^^^^^^^^^^^^^^^^^^^^^^^^^^^^^^^
  File "C:\Users\paulj\AppData\Local\Programs\Python\Python311\Lib\site-packages\requests\api.py", line 59, in request
    return session.request(method=method, url=url, **kwargs)
           ^^^^^^^^^^^^^^^^^^^^^^^^^^^^^^^^^^^^^^^^^^^^^^^^^
  File "C:\Users\paulj\AppData\Local\Programs\Python\Python311\Lib\site-packages\requests\sessions.py", line 589, in request
    resp = self.send(prep, **send_kwargs)
           ^^^^^^^^^^^^^^^^^^^^^^^^^^^^^^
  File "C:\Users\paulj\AppData\Local\Programs\Python\Python311\Lib\site-packages\requests\sessions.py", line 703, in send
    r = adapter.send(request, **kwargs)
        ^^^^^^^^^^^^^^^^^^^^^^^^^^^^^^^
  File "C:\Users\paulj\AppData\Local\Programs\Python\Python311\Lib\site-packages\requests\adapters.py", line 519, in send
    raise ConnectionError(e, request=request)
requests.exceptions.ConnectionError: HTTPConnectionPool(host='127.0.0.1', port=5000): Max retries exceeded with url: /getProducts (Caused by NewConnectionError('<urllib3.connection.HTTPConnection object at 0x000001797A55C890>: Failed to establish a new connection: [WinError 10061] No connection could be made because the target machine actively refused it'))

======================================================================
ERROR: test_getTitles (__main__.TestAPIEndpoints.test_getTitles)
----------------------------------------------------------------------
Traceback (most recent call last):
  File "C:\Users\paulj\AppData\Local\Programs\Python\Python311\Lib\site-packages\urllib3\connection.py", line 174, in _new_conn
    conn = connection.create_connection(
           ^^^^^^^^^^^^^^^^^^^^^^^^^^^^^
  File "C:\Users\paulj\AppData\Local\Programs\Python\Python311\Lib\site-packages\urllib3\util\connection.py", line 95, in create_connection
    raise err
  File "C:\Users\paulj\AppData\Local\Programs\Python\Python311\Lib\site-packages\urllib3\util\connection.py", line 85, in create_connection
    sock.connect(sa)
ConnectionRefusedError: [WinError 10061] No connection could be made because the target machine actively refused it

During handling of the above exception, another exception occurred:

Traceback (most recent call last):
  File "C:\Users\paulj\AppData\Local\Programs\Python\Python311\Lib\site-packages\urllib3\connectionpool.py", line 703, in urlopen
    httplib_response = self._make_request(
                       ^^^^^^^^^^^^^^^^^^^
  File "C:\Users\paulj\AppData\Local\Programs\Python\Python311\Lib\site-packages\urllib3\connectionpool.py", line 398, in _make_request
    conn.request(method, url, **httplib_request_kw)
  File "C:\Users\paulj\AppData\Local\Programs\Python\Python311\Lib\site-packages\urllib3\connection.py", line 239, in request
    super(HTTPConnection, self).request(method, url, body=body, headers=headers)
  File "C:\Users\paulj\AppData\Local\Programs\Python\Python311\Lib\http\client.py", line 1282, in request
    self._send_request(method, url, body, headers, encode_chunked)
  File "C:\Users\paulj\AppData\Local\Programs\Python\Python311\Lib\http\client.py", line 1328, in _send_request
    self.endheaders(body, encode_chunked=encode_chunked)
  File "C:\Users\paulj\AppData\Local\Programs\Python\Python311\Lib\http\client.py", line 1277, in endheaders
    self._send_output(message_body, encode_chunked=encode_chunked)
  File "C:\Users\paulj\AppData\Local\Programs\Python\Python311\Lib\http\client.py", line 1037, in _send_output
    self.send(msg)
  File "C:\Users\paulj\AppData\Local\Programs\Python\Python311\Lib\http\client.py", line 975, in send
    self.connect()
  File "C:\Users\paulj\AppData\Local\Programs\Python\Python311\Lib\site-packages\urllib3\connection.py", line 205, in connect
    conn = self._new_conn()
           ^^^^^^^^^^^^^^^^
  File "C:\Users\paulj\AppData\Local\Programs\Python\Python311\Lib\site-packages\urllib3\connection.py", line 186, in _new_conn
    raise NewConnectionError(
urllib3.exceptions.NewConnectionError: <urllib3.connection.HTTPConnection object at 0x000001797A5CE310>: Failed to establish a new connection: [WinError 10061] No connection could be made because the target machine actively refused it

During handling of the above exception, another exception occurred:

Traceback (most recent call last):
  File "C:\Users\paulj\AppData\Local\Programs\Python\Python311\Lib\site-packages\requests\adapters.py", line 486, in send
    resp = conn.urlopen(
           ^^^^^^^^^^^^^
  File "C:\Users\paulj\AppData\Local\Programs\Python\Python311\Lib\site-packages\urllib3\connectionpool.py", line 787, in urlopen
    retries = retries.increment(
              ^^^^^^^^^^^^^^^^^^
  File "C:\Users\paulj\AppData\Local\Programs\Python\Python311\Lib\site-packages\urllib3\util\retry.py", line 592, in increment
    raise MaxRetryError(_pool, url, error or ResponseError(cause))
urllib3.exceptions.MaxRetryError: HTTPConnectionPool(host='127.0.0.1', port=5000): Max retries exceeded with url: /getTitles (Caused by NewConnectionError('<urllib3.connection.HTTPConnection object at 0x000001797A5CE310>: Failed to establish a new connection: [WinError 10061] No connection could be made because the target machine actively refused it'))

During handling of the above exception, another exception occurred:

Traceback (most recent call last):
  File "c:\Users\paulj\OneDrive\Desktop\WS-2024\AssignmentUnitTest.py", line 23, in test_getTitles
    response = requests.get(url)
               ^^^^^^^^^^^^^^^^^
  File "C:\Users\paulj\AppData\Local\Programs\Python\Python311\Lib\site-packages\requests\api.py", line 73, in get
    return request("get", url, params=params, **kwargs)
           ^^^^^^^^^^^^^^^^^^^^^^^^^^^^^^^^^^^^^^^^^^^^
  File "C:\Users\paulj\AppData\Local\Programs\Python\Python311\Lib\site-packages\requests\api.py", line 59, in request
    return session.request(method=method, url=url, **kwargs)
           ^^^^^^^^^^^^^^^^^^^^^^^^^^^^^^^^^^^^^^^^^^^^^^^^^
  File "C:\Users\paulj\AppData\Local\Programs\Python\Python311\Lib\site-packages\requests\sessions.py", line 589, in request
    resp = self.send(prep, **send_kwargs)
           ^^^^^^^^^^^^^^^^^^^^^^^^^^^^^^
  File "C:\Users\paulj\AppData\Local\Programs\Python\Python311\Lib\site-packages\requests\sessions.py", line 703, in send
    r = adapter.send(request, **kwargs)
        ^^^^^^^^^^^^^^^^^^^^^^^^^^^^^^^
  File "C:\Users\paulj\AppData\Local\Programs\Python\Python311\Lib\site-packages\requests\adapters.py", line 519, in send
    raise ConnectionError(e, request=request)
requests.exceptions.ConnectionError: HTTPConnectionPool(host='127.0.0.1', port=5000): Max retries exceeded with url: /getTitles (Caused by NewConnectionError('<urllib3.connection.HTTPConnection object at 0x000001797A5CE310>: Failed to establish a new connection: [WinError 10061] No connection could be made because the target machine actively refused it'))

======================================================================
ERROR: test_insertProduct (__main__.TestAPIEndpoints.test_insertProduct)
----------------------------------------------------------------------
Traceback (most recent call last):
  File "C:\Users\paulj\AppData\Local\Programs\Python\Python311\Lib\site-packages\urllib3\connection.py", line 174, in _new_conn
    conn = connection.create_connection(
           ^^^^^^^^^^^^^^^^^^^^^^^^^^^^^
  File "C:\Users\paulj\AppData\Local\Programs\Python\Python311\Lib\site-packages\urllib3\util\connection.py", line 95, in create_connection
    raise err
  File "C:\Users\paulj\AppData\Local\Programs\Python\Python311\Lib\site-packages\urllib3\util\connection.py", line 85, in create_connection
    sock.connect(sa)
ConnectionRefusedError: [WinError 10061] No connection could be made because the target machine actively refused it

During handling of the above exception, another exception occurred:

Traceback (most recent call last):
  File "C:\Users\paulj\AppData\Local\Programs\Python\Python311\Lib\site-packages\urllib3\connectionpool.py", line 703, in urlopen
    httplib_response = self._make_request(
                       ^^^^^^^^^^^^^^^^^^^
  File "C:\Users\paulj\AppData\Local\Programs\Python\Python311\Lib\site-packages\urllib3\connectionpool.py", line 398, in _make_request
    conn.request(method, url, **httplib_request_kw)
  File "C:\Users\paulj\AppData\Local\Programs\Python\Python311\Lib\site-packages\urllib3\connection.py", line 239, in request
    super(HTTPConnection, self).request(method, url, body=body, headers=headers)
  File "C:\Users\paulj\AppData\Local\Programs\Python\Python311\Lib\http\client.py", line 1282, in request
    self._send_request(method, url, body, headers, encode_chunked)
  File "C:\Users\paulj\AppData\Local\Programs\Python\Python311\Lib\http\client.py", line 1328, in _send_request
    self.endheaders(body, encode_chunked=encode_chunked)
  File "C:\Users\paulj\AppData\Local\Programs\Python\Python311\Lib\http\client.py", line 1277, in endheaders
    self._send_output(message_body, encode_chunked=encode_chunked)
  File "C:\Users\paulj\AppData\Local\Programs\Python\Python311\Lib\http\client.py", line 1037, in _send_output
    self.send(msg)
  File "C:\Users\paulj\AppData\Local\Programs\Python\Python311\Lib\http\client.py", line 975, in send
    self.connect()
  File "C:\Users\paulj\AppData\Local\Programs\Python\Python311\Lib\site-packages\urllib3\connection.py", line 205, in connect
    conn = self._new_conn()
           ^^^^^^^^^^^^^^^^
  File "C:\Users\paulj\AppData\Local\Programs\Python\Python311\Lib\site-packages\urllib3\connection.py", line 186, in _new_conn
    raise NewConnectionError(
urllib3.exceptions.NewConnectionError: <urllib3.connection.HTTPConnection object at 0x000001797A5D4B90>: Failed to establish a new connection: [WinError 10061] No connection could be made because the target machine actively refused it

During handling of the above exception, another exception occurred:

Traceback (most recent call last):
  File "C:\Users\paulj\AppData\Local\Programs\Python\Python311\Lib\site-packages\requests\adapters.py", line 486, in send
    resp = conn.urlopen(
           ^^^^^^^^^^^^^
  File "C:\Users\paulj\AppData\Local\Programs\Python\Python311\Lib\site-packages\urllib3\connectionpool.py", line 787, in urlopen
    retries = retries.increment(
              ^^^^^^^^^^^^^^^^^^
  File "C:\Users\paulj\AppData\Local\Programs\Python\Python311\Lib\site-packages\urllib3\util\retry.py", line 592, in increment
    raise MaxRetryError(_pool, url, error or ResponseError(cause))
urllib3.exceptions.MaxRetryError: HTTPConnectionPool(host='127.0.0.1', port=5000): Max retries exceeded with url: /insertProduct?api_key=custom_api_key (Caused by NewConnectionError('<urllib3.connection.HTTPConnection object at 0x000001797A5D4B90>: Failed to establish a new connection: [WinError 10061] No connection could be made because the target machine actively refused it'))

During handling of the above exception, another exception occurred:

Traceback (most recent call last):
  File "c:\Users\paulj\OneDrive\Desktop\WS-2024\AssignmentUnitTest.py", line 35, in test_insertProduct
    response = requests.post(url, json=data, params=params)
               ^^^^^^^^^^^^^^^^^^^^^^^^^^^^^^^^^^^^^^^^^^^^
  File "C:\Users\paulj\AppData\Local\Programs\Python\Python311\Lib\site-packages\requests\api.py", line 115, in post
    return request("post", url, data=data, json=json, **kwargs)
           ^^^^^^^^^^^^^^^^^^^^^^^^^^^^^^^^^^^^^^^^^^^^^^^^^^^^
  File "C:\Users\paulj\AppData\Local\Programs\Python\Python311\Lib\site-packages\requests\api.py", line 59, in request
    return session.request(method=method, url=url, **kwargs)
           ^^^^^^^^^^^^^^^^^^^^^^^^^^^^^^^^^^^^^^^^^^^^^^^^^
  File "C:\Users\paulj\AppData\Local\Programs\Python\Python311\Lib\site-packages\requests\sessions.py", line 589, in request
    resp = self.send(prep, **send_kwargs)
           ^^^^^^^^^^^^^^^^^^^^^^^^^^^^^^
  File "C:\Users\paulj\AppData\Local\Programs\Python\Python311\Lib\site-packages\requests\sessions.py", line 703, in send
    r = adapter.send(request, **kwargs)
        ^^^^^^^^^^^^^^^^^^^^^^^^^^^^^^^
  File "C:\Users\paulj\AppData\Local\Programs\Python\Python311\Lib\site-packages\requests\adapters.py", line 519, in send
    raise ConnectionError(e, request=request)
requests.exceptions.ConnectionError: HTTPConnectionPool(host='127.0.0.1', port=5000): Max retries exceeded with url: /insertProduct?api_key=custom_api_key (Caused by NewConnectionError('<urllib3.connection.HTTPConnection object at 0x000001797A5D4B90>: Failed to establish a new connection: [WinError 10061] No connection could be made because the target machine actively refused it'))

----------------------------------------------------------------------
Ran 4 tests in 8.127s

FAILED (errors=4)
